

<mujoco>

  <compiler angle="radian" meshdir="assets" autolimits="true"/>
  <option integrator="implicitfast"/>

  <default>
    
       <default class="iiwa">
         <material specular="0.5" shininess="0.25" />
         <joint axis="0 0 1" />
         <general gaintype="fixed" biastype="affine" gainprm="2000" biasprm="0 -2000 -200" />
         <default class="joint1">
           <joint range="-2.96706 2.96706" />
           <general ctrlrange="-2.96706 2.96706" />
           <default class="joint2">
             <joint range="-2.0944 2.0944" />
             <general ctrlrange="-2.0944 2.0944" />
           </default>
         </default>
         <default class="joint3">
           <joint range="-3.05433 3.05433" />
           <general ctrlrange="-3.05433 3.05433" />
         </default>
         <default class="visual">
           <geom type="mesh" contype="0" conaffinity="0" group="2" material="gray" mass="0"/>
         </default>
         <default class="inertia">
           <geom type="mesh" group="4" />
         </default>
         <default class="collision">
           <geom group="3"   mass="0"/>
         </default>
         <site size="0.001" rgba="1 0 0 1" group="4" />
       </default>
   
  </default>

  <asset>
    <!-- floor  -->
    <texture  name="grid" type="2d" builtin="checker" width="512" height="512" rgb1=".1 .2 .3" rgb2=".2 .3 .4"/>
    <material name="grid" texture="grid" texrepeat="1 1" texuniform="true" reflectance=".2"/>
    <!-- robot  -->
    <material class="iiwa" name="gray" rgba="0.4 0.4 0.4 1"/><material class="iiwa" name="light_gray" rgba="0.6 0.6 0.6 1"/><material class="iiwa" name="black" rgba="0 0 0 1"/><material class="iiwa" name="orange" rgba="1 0.423529 0.0392157 1"/><material class="iiwa" name="light_orange" rgba="1 0.749 0 1"/><material class="iiwa" name="green" rgba="0.11 1 0 1"/><mesh file="/Users/mohammadhamid/Mujoco/Models/iiwa/assets/common/band.obj"/>
<mesh file="/Users/mohammadhamid/Mujoco/Models/iiwa/assets/common/kuka.obj"/>
<mesh file="/Users/mohammadhamid/Mujoco/Models/iiwa/assets/common/link_3.obj"/>
<mesh file="/Users/mohammadhamid/Mujoco/Models/iiwa/assets/common/link_3_i.obj"/>
<mesh file="/Users/mohammadhamid/Mujoco/Models/iiwa/assets/common/link_4.obj"/>
<mesh file="/Users/mohammadhamid/Mujoco/Models/iiwa/assets/common/link_4_orange.obj"/>
<mesh file="/Users/mohammadhamid/Mujoco/Models/iiwa/assets/common/link_4_grey.obj"/>
<mesh file="/Users/mohammadhamid/Mujoco/Models/iiwa/assets/common/link_5.obj"/>
<mesh file="/Users/mohammadhamid/Mujoco/Models/iiwa/assets/common/link_5_i.obj"/>
<mesh file="/Users/mohammadhamid/Mujoco/Models/iiwa/assets/common/link_6.obj"/>
<mesh file="/Users/mohammadhamid/Mujoco/Models/iiwa/assets/common/link_6_orange.obj"/>
<mesh file="/Users/mohammadhamid/Mujoco/Models/iiwa/assets/common/link_6_grey.obj"/>
<mesh file="/Users/mohammadhamid/Mujoco/Models/iiwa/assets/common/link_7.obj"/>
<mesh file="/Users/mohammadhamid/Mujoco/Models/iiwa/assets/iiwa7/link_0.obj"/>
<mesh file="/Users/mohammadhamid/Mujoco/Models/iiwa/assets/iiwa7/link_1.obj"/>
<mesh file="/Users/mohammadhamid/Mujoco/Models/iiwa/assets/iiwa7/link_2.obj"/>
<mesh file="/Users/mohammadhamid/Mujoco/Models/iiwa/assets/iiwa7/link_2_grey.obj"/>
<mesh file="/Users/mohammadhamid/Mujoco/Models/iiwa/assets/iiwa7/link_2_orange.obj"/>

  </asset>

  <worldbody>
    <!-- floor  -->
    <geom  type="plane" size="3 3 .01" material="grid"/>
    <!-- robot  -->
    
     <light name="top" pos="0 0 2" mode="trackcom"/>
     
   <body name="base" pos="0 0 0.5" quat="0 0 0 1" childclass="iiwa">
     
     
     <geom class="visual"  mesh="link_0"   />
 
     <geom class="inertia"  mesh="link_0"    mass="5" />
   
       <geom class="collision" size="0.12" pos="0 0 0.03"  material="green" />
     <geom class="collision" size="0.08" pos="-0.08 0 0.103"  material="green" />
     <geom class="collision" size="0.08" pos="-0.08 0 0.04"  material="green" />
     <geom class="collision" size="0.1" pos="0 0 0.14"  material="green" />
   

       
 <body name="link1" pos="0 0 0.1575"  >
   
   <joint  name="joint1"      class="joint1"/>
 
   
   <geom class="visual"  mesh="link_1"   />

   <geom class="inertia"  mesh="link_1"    mass="5" />
 
     <geom class="collision" size="0.08" pos="0 0 -0.0005"  material="light_orange" />
   <geom class="collision" size="0.075" pos="0.01 -0.025 0.0425"  material="light_orange" />
   <geom class="collision" size="0.075" pos="-0.01 -0.025 0.0425"  material="light_orange" />
   <geom class="collision" size="0.07" pos="0.01 -0.045 0.1025"  material="light_orange" />
   <geom class="collision" size="0.07" pos="-0.01 -0.045 0.1025"  material="light_orange" />
 

     
<body name="link2" pos="0 0 0.1825" quat="0 0 1 1" >
 
 <joint  name="joint2"      class="joint2"/>

 
 <geom class="visual"  mesh="link_2_orange"   material="orange"  />
<geom class="visual"  mesh="link_2_grey"   />

 <geom class="inertia"  mesh="link_2"    mass="6.35" />

   <geom class="collision" size="0.095" pos="0 0 -0.01"  material="green" />
 <geom class="collision" size="0.09" pos="0 0 0.045"  material="green" />
 <geom class="collision" size="0.07" pos="-0.01 0.04 0.054"  material="green" />
 <geom class="collision" size="0.065" pos="-0.01 0.09 0.04"  material="green" />
 <geom class="collision" size="0.065" pos="-0.01 0.13 0.02"  material="green" />
 <geom class="collision" size="0.07" pos="0.01 0.04 0.054"  material="green" />
 <geom class="collision" size="0.065" pos="0.01 0.09 0.04"  material="green" />
 <geom class="collision" size="0.065" pos="0.01 0.13 0.02"  material="green" />
 <geom class="collision" size="0.075" pos="0 0.18 0"  material="green" />


   
<body name="link3" pos="0 0.1845 0" quat="0 0 1 1" >

<joint  name="joint3"      class="joint1"/>


<geom class="visual"  mesh="band"   material="light_gray"  />
<geom class="visual"  mesh="link_3"   />
<geom class="visual"  mesh="kuka"   material="black"  />

<geom class="inertia"  mesh="link_3_i"    mass="3.5" />

 <geom class="collision" size="0.075" pos="0 0 0.0355"  material="light_orange" />
<geom class="collision" size="0.06" pos="0.01 0.023 0.0855"  material="light_orange" />
<geom class="collision" size="0.055" pos="0.01 0.048 0.1255"  material="light_orange" />
<geom class="collision" size="0.06" pos="0.01 0.056 0.1755"  material="light_orange" />
<geom class="collision" size="0.06" pos="-0.01 0.023 0.0855"  material="light_orange" />
<geom class="collision" size="0.055" pos="-0.01 0.048 0.1255"  material="light_orange" />
<geom class="collision" size="0.06" pos="-0.01 0.056 0.1755"  material="light_orange" />
<geom class="collision" size="0.075" pos="0 0.045 0.2155"  material="light_orange" />
<geom class="collision" size="0.075" pos="0 0 0.2155"  material="light_orange" />


 
<body name="link4" pos="0 0 0.2155" quat="1 1 0 0" >

<joint  name="joint4"      class="joint2"/>


<geom class="visual"  mesh="link_4_orange"   material="orange"  />
<geom class="visual"  mesh="link_4_grey"   />

<geom class="inertia"  mesh="link_4"    mass="3.5" />

<geom class="collision" size="0.078" pos="0 0.01 0.046"  material="green" />
<geom class="collision" size="0.06" pos="0.01 0.06 0.052"  material="green" />
<geom class="collision" size="0.065" pos="0.01 0.12 0.034"  material="green" />
<geom class="collision" size="0.06" pos="-0.01 0.06 0.052"  material="green" />
<geom class="collision" size="0.065" pos="-0.01 0.12 0.034"  material="green" />
<geom class="collision" size="0.075" pos="0 0.184 0"  material="green" />



<body name="link5" pos="0 0.1845 0" quat="0 0 1 1" >

<joint  name="joint5"      class="joint1"/>


<geom class="visual"  mesh="band"   material="light_gray"  />
<geom class="visual"  mesh="link_5"   />
<geom class="visual"  mesh="kuka"   material="black"  />

<geom class="inertia"  mesh="link_5_i"    mass="3.5" />

<geom class="collision" size="0.075" pos="0 0 0.0335"  material="light_orange" />
<geom class="collision" size="0.05" pos="-0.012 0.031 0.0755"  material="light_orange" />
<geom class="collision" size="0.05" pos="0.012 0.031 0.0755"  material="light_orange" />
<geom class="collision" size="0.04" pos="-0.012 0.06 0.1155"  material="light_orange" />
<geom class="collision" size="0.04" pos="0.012 0.06 0.1155"  material="light_orange" />
<geom class="collision" size="0.04" pos="-0.01 0.065 0.1655"  material="light_orange" />
<geom class="collision" size="0.04" pos="0.01 0.065 0.1655"  material="light_orange" />
<geom class="collision" size="0.035" pos="-0.012 0.065 0.1855"  material="light_orange" />
<geom class="collision" size="0.035" pos="0.012 0.065 0.1855"  material="light_orange" />



<body name="link6" pos="0 0 0.2155" quat="1 1 0 0" >

<joint  name="joint6"      class="joint2"/>


<geom class="visual"  mesh="link_6_orange"   material="orange"  />
<geom class="visual"  mesh="link_6_grey"   />

<geom class="inertia"  mesh="link_6"    mass="1.8" />

<geom class="collision" size="0.055" pos="0 0 -0.059"  material="green" />
<geom class="collision" size="0.065" pos="0 -0.03 0.011"  material="green" />
<geom class="collision" size="0.08" pos="0 0 0"  material="green" />



<body name="link7" pos="0 0.081 0" quat="0 0 1 1" >

<joint  name="joint7"      class="joint3"/>


<geom class="visual"  mesh="link_7"   />

<geom class="inertia"  mesh="link_7"    mass="1.2" />

<geom class="collision" size="0.06" pos="0 0 0.001"  material="light_orange" />




</body>



</body>



</body>



</body>



</body>



</body>



 </body>



   </body>

 


   
  </worldbody>

  <contact>
     <exclude body1="base" body2="link1"/>
  </contact>

  <actuator>
    <general name="actuator1" joint="joint1" class="joint1"/> 
		<general name="actuator2" joint="joint2" class="joint2"/> 
		<general name="actuator3" joint="joint3" class="joint1"/> 
		<general name="actuator4" joint="joint4" class="joint2"/> 
		<general name="actuator5" joint="joint5" class="joint1"/> 
		<general name="actuator6" joint="joint6" class="joint2"/> 
		<general name="actuator7" joint="joint7" class="joint3"/> 
		
  </actuator>

</mujoco>
