<mujoco>
	<compiler angle="radian" meshdir="assets" autolimits="true"/>

	<option integrator="implicitfast" />

	<default>

		<default class="iiwa">
			<material specular="0.5" shininess="0.25"/>
			<joint axis="0 0 1"/>
			<general gaintype="fixed" biastype="affine" gainprm="2000" biasprm="0 -2000 -200"/>
			<default class="joint1">
				<joint range="-2.96706 2.96706"/>
				<general ctrlrange="-2.96706 2.96706"/>
				<default class="joint2">
					<joint range="-2.0944 2.0944"/>
					<general ctrlrange="-2.0944 2.0944"/>
				</default>
			</default>
			<default class="joint3">
				<joint range="-3.05433 3.05433"/>
				<general ctrlrange="-3.05433 3.05433"/>
			</default>
			<default class="visual">
				<geom type="mesh" contype="0" conaffinity="0" group="2" material="gray"/>
			</default>
			<default class="collision">
				<geom group="3"/>
			</default>
			<site size="0.001" rgba="1 0 0 1" group="4"/>
		</default>
	</default>

	<asset>
		<material class="iiwa" name="gray" rgba="0.4 0.4 0.4 1"/>
		<material class="iiwa" name="light_gray" rgba="0.6 0.6 0.6 1"/>
		<material class="iiwa" name="black" rgba="0 0 0 1"/>
		<material class="iiwa" name="orange" rgba="1 0.423529 0.0392157 1"/>
		<mesh file="/Users/mohammadhamid/Mujoco/Models/iiwa/assets/iiwa7/link_0.obj"/>
		<mesh file="/Users/mohammadhamid/Mujoco/Models/iiwa/assets/iiwa7/link_1.obj"/>
		<mesh file="/Users/mohammadhamid/Mujoco/Models/iiwa/assets/iiwa7/link_2.obj"/>
		<mesh file="/Users/mohammadhamid/Mujoco/Models/iiwa/assets/iiwa7/link_3.obj"/>
		<mesh file="/Users/mohammadhamid/Mujoco/Models/iiwa/assets/iiwa7/link_4.obj"/>
		<mesh file="/Users/mohammadhamid/Mujoco/Models/iiwa/assets/iiwa7/link_5.obj"/>
		<mesh file="/Users/mohammadhamid/Mujoco/Models/iiwa/assets/iiwa7/link_6.obj"/>
		<mesh file="/Users/mohammadhamid/Mujoco/Models/iiwa/assets/iiwa7/link_7.obj"/>

	</asset>

	<worldbody>

		<light name="top_0" pos="0 0 2" mode="trackcom"/>

		<body name="base_0" pos="0 0 0" quat="0.984807753012208 0.0 -0.17364817766693033 0.0"
			childclass="iiwa">


			<inertial mass="5" pos="-0.1 0 0.07" diaginertia="0.05 0.06 0.03" />

			<geom class="visual" mesh="link_0" />

			<geom class="collision" size="0.12" pos="0 0 0.03" />
			<geom class="collision" size="0.08" pos="-0.08 0 0.103" />
			<geom class="collision" size="0.08" pos="-0.08 0 0.04" />
			<geom class="collision" size="0.1" pos="0 0 0.14" />


			<body name="link1_0" pos="0 0 0.1575">
				<joint name="joint1_0" class="joint1" />
				<inertial mass="5" pos="-0.1 0 0.07" diaginertia="0.05 0.06 0.03" />

				<geom class="visual" mesh="link_1" />

				<geom class="collision" size="0.08" pos="0 0 -0.0005" />
				<geom class="collision" size="0.075" pos="0.01 -0.025 0.0425" />
				<geom class="collision" size="0.075" pos="-0.01 -0.025 0.0425" />
				<geom class="collision" size="0.07" pos="0.01 -0.045 0.1025" />
				<geom class="collision" size="0.07" pos="-0.01 -0.045 0.1025" />


				<body name="link2_0" pos="0 0 0.1825" quat="0 0 1 1">

					<joint name="joint2_0" class="joint2" />


					<inertial mass="6.35" pos="0.0003 0.059 0.042" diaginertia="0.0305 0.0304 0.011" />

					<geom class="visual" mesh="link_2" material="orange" />

					<geom class="collision" size="0.095" pos="0 0 -0.01" />
					<geom class="collision" size="0.09" pos="0 0 0.045" />
					<geom class="collision" size="0.07" pos="-0.01 0.04 0.054" />
					<geom class="collision" size="0.065" pos="-0.01 0.09 0.04" />
					<geom class="collision" size="0.065" pos="-0.01 0.13 0.02" />
					<geom class="collision" size="0.07" pos="0.01 0.04 0.054" />
					<geom class="collision" size="0.065" pos="0.01 0.09 0.04" />
					<geom class="collision" size="0.065" pos="0.01 0.13 0.02" />
					<geom class="collision" size="0.075" pos="0 0.18 0" />


					<body name="link3_0" pos="0 0.1845 0" quat="0 0 1 1">

						<joint name="joint3_0" class="joint1" />


						<inertial mass="3.5" pos="0 0.03 0.13" diaginertia="0.025 0.0238 0.0076" />

						<geom class="visual" mesh="link_3" />

						<geom class="collision" size="0.075" pos="0 0 0.0355" />
						<geom class="collision" size="0.06" pos="0.01 0.023 0.0855" />
						<geom class="collision" size="0.055" pos="0.01 0.048 0.1255" />
						<geom class="collision" size="0.06" pos="0.01 0.056 0.1755" />
						<geom class="collision" size="0.06" pos="-0.01 0.023 0.0855" />
						<geom class="collision" size="0.055" pos="-0.01 0.048 0.1255" />
						<geom class="collision" size="0.06" pos="-0.01 0.056 0.1755" />
						<geom class="collision" size="0.075" pos="0 0.045 0.2155" />
						<geom class="collision" size="0.075" pos="0 0 0.2155" />


						<body name="link4_0" pos="0 0 0.2155" quat="1 1 0 0">

							<joint name="joint4_0" class="joint2" />


							<inertial mass="3.5" pos="0 0.067 0.034"
								diaginertia="0.017 0.0164 0.006" />

							<geom class="visual" mesh="link_4" material="orange" />

							<geom class="collision" size="0.078" pos="0 0.01 0.046" />
							<geom class="collision" size="0.06" pos="0.01 0.06 0.052" />
							<geom class="collision" size="0.065" pos="0.01 0.12 0.034" />
							<geom class="collision" size="0.06" pos="-0.01 0.06 0.052" />
							<geom class="collision" size="0.065" pos="-0.01 0.12 0.034" />
							<geom class="collision" size="0.075" pos="0 0.184 0" />


							<body name="link5_0" pos="0 0.1845 0" quat="0 0 1 1">

								<joint name="joint5_0" class="joint1" />


								<inertial mass="3.5" pos="0.0001 0.021 0.076"
									diaginertia="0.01 0.0087 0.00449" />

								<geom class="visual" mesh="link_5" />

								<geom class="collision" size="0.075" pos="0 0 0.0335" />
								<geom class="collision" size="0.05" pos="-0.012 0.031 0.0755" />
								<geom class="collision" size="0.05" pos="0.012 0.031 0.0755" />
								<geom class="collision" size="0.04" pos="-0.012 0.06 0.1155" />
								<geom class="collision" size="0.04" pos="0.012 0.06 0.1155" />
								<geom class="collision" size="0.04" pos="-0.01 0.065 0.1655" />
								<geom class="collision" size="0.04" pos="0.01 0.065 0.1655" />
								<geom class="collision" size="0.035" pos="-0.012 0.065 0.1855" />
								<geom class="collision" size="0.035" pos="0.012 0.065 0.1855" />


								<body name="link6_0" pos="0 0 0.2155" quat="1 1 0 0">

									<joint name="joint6_0" class="joint2" />


									<inertial mass="1.8" pos="0 0.0006 0.0004"
										diaginertia="0.0049 0.0047 0.0036" />

									<geom class="visual" mesh="link_6" />

									<geom class="collision" size="0.055" pos="0 0 -0.059" />
									<geom class="collision" size="0.065" pos="0 -0.03 0.011" />
									<geom class="collision" size="0.08" pos="0 0 0" />


									<body name="link7_0" pos="0 0.081 0" quat="0 0 1 1">

										<joint name="joint7_0" class="joint3" />


										<inertial mass="1.2" pos="0 0 0.02"
											diaginertia="0.001 0.001 0.001" />

										<geom class="visual" mesh="link_7" />

										<geom class="collision" size="0.06" pos="0 0 0.001" />


									</body>


								</body>


							</body>


						</body>


					</body>


				</body>


			</body>


		</body>


		<light name="top_1" pos="0 0 2" mode="trackcom" />

		<body name="base_1" pos="1 0 0" quat="0.984807753012208 0.0 0.17364817766693033 0.0"
			childclass="iiwa">


			<inertial mass="5" pos="-0.1 0 0.07" diaginertia="0.05 0.06 0.03" />

			<geom class="visual" mesh="link_0" />

			<geom class="collision" size="0.12" pos="0 0 0.03" />
			<geom class="collision" size="0.08" pos="-0.08 0 0.103" />
			<geom class="collision" size="0.08" pos="-0.08 0 0.04" />
			<geom class="collision" size="0.1" pos="0 0 0.14" />


			<body name="link1_1" pos="0 0 0.1575">

				<joint name="joint1_1" class="joint1" />


				<inertial mass="5" pos="-0.1 0 0.07" diaginertia="0.05 0.06 0.03" />

				<geom class="visual" mesh="link_1" />

				<geom class="collision" size="0.08" pos="0 0 -0.0005" />
				<geom class="collision" size="0.075" pos="0.01 -0.025 0.0425" />
				<geom class="collision" size="0.075" pos="-0.01 -0.025 0.0425" />
				<geom class="collision" size="0.07" pos="0.01 -0.045 0.1025" />
				<geom class="collision" size="0.07" pos="-0.01 -0.045 0.1025" />


				<body name="link2_1" pos="0 0 0.1825" quat="0 0 1 1">

					<joint name="joint2_1" class="joint2" />


					<inertial mass="6.35" pos="0.0003 0.059 0.042" diaginertia="0.0305 0.0304 0.011" />

					<geom class="visual" mesh="link_2" material="orange" />

					<geom class="collision" size="0.095" pos="0 0 -0.01" />
					<geom class="collision" size="0.09" pos="0 0 0.045" />
					<geom class="collision" size="0.07" pos="-0.01 0.04 0.054" />
					<geom class="collision" size="0.065" pos="-0.01 0.09 0.04" />
					<geom class="collision" size="0.065" pos="-0.01 0.13 0.02" />
					<geom class="collision" size="0.07" pos="0.01 0.04 0.054" />
					<geom class="collision" size="0.065" pos="0.01 0.09 0.04" />
					<geom class="collision" size="0.065" pos="0.01 0.13 0.02" />
					<geom class="collision" size="0.075" pos="0 0.18 0" />


					<body name="link3_1" pos="0 0.1845 0" quat="0 0 1 1">

						<joint name="joint3_1" class="joint1" />


						<inertial mass="3.5" pos="0 0.03 0.13" diaginertia="0.025 0.0238 0.0076" />

						<geom class="visual" mesh="link_3" />

						<geom class="collision" size="0.075" pos="0 0 0.0355" />
						<geom class="collision" size="0.06" pos="0.01 0.023 0.0855" />
						<geom class="collision" size="0.055" pos="0.01 0.048 0.1255" />
						<geom class="collision" size="0.06" pos="0.01 0.056 0.1755" />
						<geom class="collision" size="0.06" pos="-0.01 0.023 0.0855" />
						<geom class="collision" size="0.055" pos="-0.01 0.048 0.1255" />
						<geom class="collision" size="0.06" pos="-0.01 0.056 0.1755" />
						<geom class="collision" size="0.075" pos="0 0.045 0.2155" />
						<geom class="collision" size="0.075" pos="0 0 0.2155" />


						<body name="link4_1" pos="0 0 0.2155" quat="1 1 0 0">

							<joint name="joint4_1" class="joint2" />


							<inertial mass="3.5" pos="0 0.067 0.034"
								diaginertia="0.017 0.0164 0.006" />

							<geom class="visual" mesh="link_4" material="orange" />

							<geom class="collision" size="0.078" pos="0 0.01 0.046" />
							<geom class="collision" size="0.06" pos="0.01 0.06 0.052" />
							<geom class="collision" size="0.065" pos="0.01 0.12 0.034" />
							<geom class="collision" size="0.06" pos="-0.01 0.06 0.052" />
							<geom class="collision" size="0.065" pos="-0.01 0.12 0.034" />
							<geom class="collision" size="0.075" pos="0 0.184 0" />


							<body name="link5_1" pos="0 0.1845 0" quat="0 0 1 1">

								<joint name="joint5_1" class="joint1" />


								<inertial mass="3.5" pos="0.0001 0.021 0.076"
									diaginertia="0.01 0.0087 0.00449" />

								<geom class="visual" mesh="link_5" />

								<geom class="collision" size="0.075" pos="0 0 0.0335" />
								<geom class="collision" size="0.05" pos="-0.012 0.031 0.0755" />
								<geom class="collision" size="0.05" pos="0.012 0.031 0.0755" />
								<geom class="collision" size="0.04" pos="-0.012 0.06 0.1155" />
								<geom class="collision" size="0.04" pos="0.012 0.06 0.1155" />
								<geom class="collision" size="0.04" pos="-0.01 0.065 0.1655" />
								<geom class="collision" size="0.04" pos="0.01 0.065 0.1655" />
								<geom class="collision" size="0.035" pos="-0.012 0.065 0.1855" />
								<geom class="collision" size="0.035" pos="0.012 0.065 0.1855" />


								<body name="link6_1" pos="0 0 0.2155" quat="1 1 0 0">

									<joint name="joint6_1" class="joint2" />


									<inertial mass="1.8" pos="0 0.0006 0.0004"
										diaginertia="0.0049 0.0047 0.0036" />

									<geom class="visual" mesh="link_6" />

									<geom class="collision" size="0.055" pos="0 0 -0.059" />
									<geom class="collision" size="0.065" pos="0 -0.03 0.011" />
									<geom class="collision" size="0.08" pos="0 0 0" />


									<body name="link7_1" pos="0 0.081 0" quat="0 0 1 1">

										<joint name="joint7_1" class="joint3" />


										<inertial mass="1.2" pos="0 0 0.02"
											diaginertia="0.001 0.001 0.001" />

										<geom class="visual" mesh="link_7" />

										<geom class="collision" size="0.06" pos="0 0 0.001" />


									</body>


								</body>


							</body>


						</body>


					</body>


				</body>


			</body>


		</body>


	</worldbody>

	<contact>
		<exclude body1="base_0" body2="link1_0" />
		<exclude body1="base_1" body2="link1_1" />
	</contact>

	<actuator>
		<general name="actuator1_0" joint="joint1_0" class="joint1" />
		<general name="actuator2_0" joint="joint2_0" class="joint2" />
		<general name="actuator3_0" joint="joint3_0" class="joint1" />
		<general name="actuator4_0" joint="joint4_0" class="joint2" />
		<general name="actuator5_0" joint="joint5_0" class="joint1" />
		<general name="actuator6_0" joint="joint6_0" class="joint2" />
		<general name="actuator7_0" joint="joint7_0" class="joint3" />
		<general name="actuator1_1" joint="joint1_1" class="joint1" />
		<general name="actuator2_1" joint="joint2_1" class="joint2" />
		<general name="actuator3_1" joint="joint3_1" class="joint1" />
		<general name="actuator4_1" joint="joint4_1" class="joint2" />
		<general name="actuator5_1" joint="joint5_1" class="joint1" />
		<general name="actuator6_1" joint="joint6_1" class="joint2" />
		<general name="actuator7_1" joint="joint7_1" class="joint3" />

	</actuator>

</mujoco>